Workbook

Sheet dados_solicitacoes
A1: Número da Solicitação | B1: Orgão | C1: Unidade gestora | D1: Tipo da solicitação | E1: Número da ata | F1: Objeto | G1: Núcleo Pertencente | H1: Data da solicitação | I1: Situação do Processo | J1: Situação Atual | K1: Andamento no PE Integrado | L1: Comparação | M1: Responsável | N1: Andamento SEI | O1: Encaminhado / Setor | P1: SEI | Q1: Status da Coluna M
A2: C.002-ARP.0080.00.2025.GOV.FES-PE.PE | B2: =IFERROR(__xludf.DUMMYFUNCTION("REGEXEXTRACT(A2, ""\.(?:GOV|EXT)\.([A-Z0-9\-]+)"") "),"FES-PE") -> FES-PE | C2: HOSPITAL REGIONAL DO AGRESTE DR.WALDEMIRO FERREIRA | D2: Adesão | E2: =IFERROR(__xludf.DUMMYFUNCTION("REGEXEXTRACT(A2, ""-(.*)"")"),"ARP.0080.00.2025.GOV.FES-PE.PE") -> ARP.0080.00.2025.GOV.FES-PE.PE | F2: Formação de Registro de Preços para o fornecimento eventual de MEDICAMENTOS INJETÁVEIS VOL. 1 visando atender as necessidades do Hospital Jaboatão Prazeres. | G2: NFOCPO | H2: 45933 | I2: Cancelada | J2: =VLOOKUP(A2,'TODOS OS PROCESSOS ATUALIZADOS '!A:I,7,0) -> Cancelada | K2: Cancelado | L2: =IFERROR(IF(J2=I2, "Item não atualizado", "Item atualizado"), "Item não localizado") -> Item não atualizado | N2: Cancelado | O2: SEI não localizado
A3: A.031-ARP.0001.01.2025.GOV.HUOC.PE | B3: =IFERROR(__xludf.DUMMYFUNCTION("REGEXEXTRACT(A3, ""\.(?:GOV|EXT)\.([A-Z0-9\-]+)"") "),"HUOC") -> HUOC | C3: HOSPITAL REGIONAL DO AGRESTE DR.WALDEMIRO FERREIRA | D3: Adesão | E3: =IFERROR(__xludf.DUMMYFUNCTION("REGEXEXTRACT(A3, ""-(.*)"")"),"ARP.0001.01.2025.GOV.HUOC.PE") -> ARP.0001.01.2025.GOV.HUOC.PE | F3: Registro de Preços para o fornecimento eventual de MEDICAMENTOS CONTROLADOS, CLÍNICOS RESPIRATÓRIOS E MANIPULADOS (SEI Nº 0040609437.000157/2024-48) | G3: NFOCPO | H3: 45943 | I3: Cancelada | J3: =VLOOKUP(A3,'TODOS OS PROCESSOS ATUALIZADOS '!A:I,7,0) -> Em configuração | K3: Cancelar Com o Suporte | L3: =IFERROR(IF(J3=I3, "Item não atualizado", "Item atualizado"), "Item não localizado") -> Item atualizado | N3: Cancelar Com o Suporte | O3: SEI não localizado
A4: A.029-ARP.0001.01.2025.GOV.HUOC.PE | B4: =IFERROR(__xludf.DUMMYFUNCTION("REGEXEXTRACT(A4, ""\.(?:GOV|EXT)\.([A-Z0-9\-]+)"") "),"HUOC") -> HUOC | C4: HOSPITAL REGIONAL DO AGRESTE DR.WALDEMIRO FERREIRA | D4: Adesão | E4: =IFERROR(__xludf.DUMMYFUNCTION("REGEXEXTRACT(A4, ""-(.*)"")"),"ARP.0001.01.2025.GOV.HUOC.PE") -> ARP.0001.01.2025.GOV.HUOC.PE | F4: Registro de Preços para o fornecimento eventual de MEDICAMENTOS CONTROLADOS, CLÍNICOS RESPIRATÓRIOS E MANIPULADOS (SEI Nº 0040609437.000157/2024-48) | G4: NFOCPO | H4: 45933 | I4: Concluído | J4: =VLOOKUP(A4,'TODOS OS PROCESSOS ATUALIZADOS '!A:I,7,0) -> Autorizada Sucesso | K4: Concluído | L4: =IFERROR(IF(J4=I4, "Item não atualizado", "Item atualizado"), "Item não localizado") -> Item atualizado | N4: Em andamento | O4: Enviado ao JURIDICO | P4: 2300001213.000370/2025-49
A5: A.027-ARP.0089.01.2024.GOV.HUOC.PE | B5: =IFERROR(__xludf.DUMMYFUNCTION("REGEXEXTRACT(A5, ""\.(?:GOV|EXT)\.([A-Z0-9\-]+)"") "),"HUOC") -> HUOC | C5: HOSPITAL REGIONAL DO AGRESTE DR.WALDEMIRO FERREIRA | D5: Adesão | E5: =IFERROR(__xludf.DUMMYFUNCTION("REGEXEXTRACT(A5, ""-(.*)"")"),"ARP.0089.01.2024.GOV.HUOC.PE") -> ARP.0089.01.2024.GOV.HUOC.PE | F5: Registro de Preços para o fornecimento eventual de MEDICAMENTOS ANTIMICROBIANOS (SEI Nº 0040609437.000129/2024-21) | H5: 45912 | I5: Cancelada | J5: =VLOOKUP(A5,'TODOS OS PROCESSOS ATUALIZADOS '!A:I,7,0) -> Cancelada por fim vigencia ATA | K5: Cancelado | L5: =IFERROR(IF(J5=I5, "Item não atualizado", "Item atualizado"), "Item não localizado") -> Item atualizado | N5: Cancelado | O5: SEI não localizado
A6: A.024-ARP.0119.01.2024.GOV.HUOC.PE | B6: =IFERROR(__xludf.DUMMYFUNCTION("REGEXEXTRACT(A6, ""\.(?:GOV|EXT)\.([A-Z0-9\-]+)"") "),"HUOC") -> HUOC | C6: HOSPITAL REGIONAL DO AGRESTE DR.WALDEMIRO FERREIRA | D6: Adesão | E6: =IFERROR(__xludf.DUMMYFUNCTION("REGEXEXTRACT(A6, ""-(.*)"")"),"ARP.0119.01.2024.GOV.HUOC.PE") -> ARP.0119.01.2024.GOV.HUOC.PE | F6: Registro de Preços para a eventual aquisição de Medicamentos Clínicos Gerais 4 (SEI Nº 0040609437.000172/2024-96) | G6: NFOCPO | H6: 45923 | I6: Concluído | J6: =VLOOKUP(A6,'TODOS OS PROCESSOS ATUALIZADOS '!A:I,7,0) -> Autorizada Sucesso | K6: Concluído | L6: =IFERROR(IF(J6=I6, "Item não atualizado", "Item atualizado"), "Item não localizado") -> Item atualizado | N6: Concluído | O6: Enviado ao NOF | P6: 2300001213.000405/2025-40
A7: A.019-ARP.0013.00.2025.GOV.FUNDARPE.PE | B7: =IFERROR(__xludf.DUMMYFUNCTION("REGEXEXTRACT(A7, ""\.(?:GOV|EXT)\.([A-Z0-9\-]+)"") "),"FUNDARPE") -> FUNDARPE | C7: HOSPITAL REGIONAL DO AGRESTE DR.WALDEMIRO FERREIRA | D7: Adesão | E7: =IFERROR(__xludf.DUMMYFUNCTION("REGEXEXTRACT(A7, ""-(.*)"")"),"ARP.0013.00.2025.GOV.FUNDARPE.PE") -> ARP.0013.00.2025.GOV.FUNDARPE.PE | F7: Formação de Registro de Preços para contratação eventual de prestação de serviços de Alimentação Pronta (marmitex e lanche) e Buffet (coffee break, coquetel volante e self-service), sem a locação de espaço para atender as demandas dos projetos, eventos, ciclos tradicionais, feiras, festivais e demais ações e/ou eventos culturais, promovidos e/ou apoiados pelo Governo de Pernambuco | G7: NAMP | H7: 45943 | I7: Concluído | J7: =VLOOKUP(A7,'TODOS OS PROCESSOS ATUALIZADOS '!A:I,7,0) -> Autorizada Sucesso | K7: Concluído | L7: =IFERROR(IF(J7=I7, "Item não atualizado", "Item atualizado"), "Item não localizado") -> Item atualizado | N7: Em andamento | O7: Enviado a GCONTRATOS | P7: 2300002942.000003/2025-73
A8: A.015-ARP.0017.00.2025.EXT.131763.PB | B8: =IFERROR(__xludf.DUMMYFUNCTION("REGEXEXTRACT(A8, ""\.(?:GOV|EXT)\.([A-Z0-9\-]+)"") "),"131763") -> 131763 | C8: HOSPITAL REGIONAL DO AGRESTE DR.WALDEMIRO FERREIRA | D8: Adesão | E8: =IFERROR(__xludf.DUMMYFUNCTION("REGEXEXTRACT(A8, ""-(.*)"")"),"ARP.0017.00.2025.EXT.131763.PB") -> ARP.0017.00.2025.EXT.131763.PB | F8: A presente Ata tem por objetivo o registro de preços PARA REGISTRO DE PREÇO PARA AQUISIÇÃO DE MEDICAMENTOS ANTIBACTERIANOS INJETÁVEIS especificado, no item 1.1 do Termo de Referência, anexo no edital de Pregão 173/2024 que é parte integrante desta Ata, assim como as propostas cujos preços tenham sido registrados, independentemente da transcrição. | G8: NFOCPO | H8: 45929 | I8: Concluído | J8: =VLOOKUP(A8,'TODOS OS PROCESSOS ATUALIZADOS '!A:I,7,0) -> Autorizada Integrado | K8: Concluído | L8: =IFERROR(IF(J8=I8, "Item não atualizado", "Item atualizado"), "Item não localizado") -> Item atualizado | M8: Daniele | N8: Em andamento | O8: Enviado a NFOCPO | P8: 2300001213.000259/2025-52
A9: A.014-ARP.0017.00.2025.EXT.131763.PB | B9: =IFERROR(__xludf.DUMMYFUNCTION("REGEXEXTRACT(A9, ""\.(?:GOV|EXT)\.([A-Z0-9\-]+)"") "),"131763") -> 131763 | C9: HOSPITAL REGIONAL DO AGRESTE DR.WALDEMIRO FERREIRA | D9: Adesão | E9: =IFERROR(__xludf.DUMMYFUNCTION("REGEXEXTRACT(A9, ""-(.*)"")"),"ARP.0017.00.2025.EXT.131763.PB") -> ARP.0017.00.2025.EXT.131763.PB | F9: A presente Ata tem por objetivo o registro de preços PARA REGISTRO DE PREÇO PARA AQUISIÇÃO DE MEDICAMENTOS ANTIBACTERIANOS INJETÁVEIS especificado, no item 1.1 do Termo de Referência, anexo no edital de Pregão 173/2024 que é parte integrante desta Ata, assim como as propostas cujos preços tenham sido registrados, independentemente da transcrição. | H9: 45917 | I9: Concluído | J9: =VLOOKUP(A9,'TODOS OS PROCESSOS ATUALIZADOS '!A:I,7,0) -> Autorizada Integrado | K9: Concluído | L9: =IFERROR(IF(J9=I9, "Item não atualizado", "Item atualizado"), "Item não localizado") -> Item atualizado | M9: Daniele | N9: Em andamento | O9: Enviado a GCONTRATOS | P9: 2300001213.000190/2025-67 | Q9: solicitação em duplicidade com A.014-ARP.0017.00.2025.EXT.131763.PB - sem efeito para conlcusão da compra
A10: A.013-ARP.0084.05.2024.GOV.CISAM.PE | B10: =IFERROR(__xludf.DUMMYFUNCTION("REGEXEXTRACT(A10, ""\.(?:GOV|EXT)\.([A-Z0-9\-]+)"") "),"CISAM") -> CISAM | C10: HOSPITAL REGIONAL DO AGRESTE DR.WALDEMIRO FERREIRA | D10: Adesão | E10: =IFERROR(__xludf.DUMMYFUNCTION("REGEXEXTRACT(A10, ""-(.*)"")"),"ARP.0084.05.2024.GOV.CISAM.PE") -> ARP.0084.05.2024.GOV.CISAM.PE | F10: REGISTRO DE PREÇOS PARA FORNECIMENTO EVENTUAL DE MOBILIARIOS MEDICO-HOSPITALAR PARA O CENTRO DE PARTO NORMAL E CASA DA GESTANTE BEBE E PUERPERA PARA RECÉM NASCIDOS, VISANDO ATENDER AS NECESSIDADES DO CISAM/UPE E DEMAIS ÓRGÃO PARTICIPANTES. | G10: NAMP | H10: 45923 | I10: Concluído | J10: =VLOOKUP(A10,'TODOS OS PROCESSOS ATUALIZADOS '!A:I,7,0) -> Autorizada Sucesso | K10: Concluído | L10: =IFERROR(IF(J10=I10, "Item não atualizado", "Item atualizado"), "Item não localizado") -> Item atualizado | N10: Em andamento | O10: Enviado ao JURIDICO | P10: 2300002544.000075/2025-11
A11: A.012-ARP.0013.02.2025.GOV.HOF.PE | B11: =IFERROR(__xludf.DUMMYFUNCTION("REGEXEXTRACT(A11, ""\.(?:GOV|EXT)\.([A-Z0-9\-]+)"") "),"HOF") -> HOF | C11: HOSPITAL REGIONAL DO AGRESTE DR.WALDEMIRO FERREIRA | D11: Adesão | E11: =IFERROR(__xludf.DUMMYFUNCTION("REGEXEXTRACT(A11, ""-(.*)"")"),"ARP.0013.02.2025.GOV.HOF.PE") -> ARP.0013.02.2025.GOV.HOF.PE | F11: REGISTRO DE PREÇOS PARA O FORNECIMENTO DE DISPOSITIVOS MÉDICOS DO TIPO INSUMOS PARA OXIGENOTERAPIA, VISANDO ATENDER AS NECESSIDADES DO HOSPITAL OTÁVIO DE FREITAS. | G11: NAEN | H11: 45924 | I11: Em configuração | J11: =VLOOKUP(A11,'TODOS OS PROCESSOS ATUALIZADOS '!A:I,7,0) -> Em configuração | K11: Em andamento | L11: =IFERROR(IF(J11=I11, "Item não atualizado", "Item atualizado"), "Item não localizado") -> Item não atualizado | M11: Elisangela | N11: Em andamento | O11: SEI não localizado | P11: Revisar com Papa | Q11: Finalizar com o nucleo
A12: A.012-ARP.0009.02.2025.GOV.FES-PE.PE | B12: =IFERROR(__xludf.DUMMYFUNCTION("REGEXEXTRACT(A12, ""\.(?:GOV|EXT)\.([A-Z0-9\-]+)"") "),"FES-PE") -> FES-PE | C12: HOSPITAL REGIONAL DO AGRESTE DR.WALDEMIRO FERREIRA | D12: Adesão | E12: =IFERROR(__xludf.DUMMYFUNCTION("REGEXEXTRACT(A12, ""-(.*)"")"),"ARP.0009.02.2025.GOV.FES-PE.PE") -> ARP.0009.02.2025.GOV.FES-PE.PE | F12: Registro de Preços para aquisição de Material Médico Hospitalar - Luvas (Unificado) | G12: NFOCPO | H12: 45943 | I12: Concluído | J12: =VLOOKUP(A12,'TODOS OS PROCESSOS ATUALIZADOS '!A:I,7,0) -> Autorizada Sucesso | K12: Concluído | L12: =IFERROR(IF(J12=I12, "Item não atualizado", "Item atualizado"), "Item não localizado") -> Item atualizado | N12: Concluído | O12: Enviado ao NOF | P12: 2300001213.000385/2025-15
A13: A.011-ARP.0080.00.2025.GOV.FES-PE.PE | B13: =IFERROR(__xludf.DUMMYFUNCTION("REGEXEXTRACT(A13, ""\.(?:GOV|EXT)\.([A-Z0-9\-]+)"") "),"FES-PE") -> FES-PE | C13: HOSPITAL REGIONAL DO AGRESTE DR.WALDEMIRO FERREIRA | D13: Adesão | E13: =IFERROR(__xludf.DUMMYFUNCTION("REGEXEXTRACT(A13, ""-(.*)"")"),"ARP.0080.00.2025.GOV.FES-PE.PE") -> ARP.0080.00.2025.GOV.FES-PE.PE | F13: Formação de Registro de Preços para o fornecimento eventual de MEDICAMENTOS INJETÁVEIS VOL. 1 visando atender as necessidades do Hospital Jaboatão Prazeres. | G13: NFOCPO | H13: 45933 | I13: Concluído | J13: =VLOOKUP(A13,'TODOS OS PROCESSOS ATUALIZADOS '!A:I,7,0) -> Autorizada Sucesso | K13: Concluído | L13: =IFERROR(IF(J13=I13, "Item não atualizado", "Item atualizado"), "Item não localizado") -> Item atualizado | N13: Em andamento | O13: Enviado a NFOCPO | P13: 2300001213.000402/2025-14
A14: A.010-ARP.0051.04.2025.GOV.PROCAPE.PE | B14: =IFERROR(__xludf.DUMMYFUNCTION("REGEXEXTRACT(A14, ""\.(?:GOV|EXT)\.([A-Z0-9\-]+)"") "),"PROCAPE") -> PROCAPE | C14: HOSPITAL REGIONAL DO AGRESTE DR.WALDEMIRO FERREIRA | D14: Adesão | E14: =IFERROR(__xludf.DUMMYFUNCTION("REGEXEXTRACT(A14, ""-(.*)"")"),"ARP.0051.04.2025.GOV.PROCAPE.PE") -> ARP.0051.04.2025.GOV.PROCAPE.PE | F14: REGISTRO DE PREÇOS PARA EVENTUAL FORNECIMENTO DE MATERIAL DE CONSUMO HOSPITALAR (MATERIAL PENSO) | G14: NFOCPO | H14: 45925 | I14: Concluído | J14: =VLOOKUP(A14,'TODOS OS PROCESSOS ATUALIZADOS '!A:I,7,0) -> Autorizada Sucesso | K14: Concluído | L14: =IFERROR(IF(J14=I14, "Item não atualizado", "Item atualizado"), "Item não localizado") -> Item atualizado | N14: Em andamento | O14: Enviado ao JURIDICO | P14: 2300001213.000360/2025-11
A15: A.008-ARP.0072.07.2025.GOV.HUOC.PE | B15: =IFERROR(__xludf.DUMMYFUNCTION("REGEXEXTRACT(A15, ""\.(?:GOV|EXT)\.([A-Z0-9\-]+)"") "),"HUOC") -> HUOC | C15: HOSPITAL REGIONAL DO AGRESTE DR.WALDEMIRO FERREIRA | D15: Adesão | E15: =IFERROR(__xludf.DUMMYFUNCTION("REGEXEXTRACT(A15, ""-(.*)"")"),"ARP.0072.07.2025.GOV.HUOC.PE") -> ARP.0072.07.2025.GOV.HUOC.PE | F15: Registro de Preços para o eventual fornecimento de MEDICAMENTOS CLÍNICOS GERAIS 6 - 18 ITENS - SEI: 0040609437.000009/2025-12 | G15: NFOCPO | H15: 45924 | I15: Cancelada | J15: =VLOOKUP(A15,'TODOS OS PROCESSOS ATUALIZADOS '!A:I,7,0) -> Em configuração | K15: Cancelar Com o Suporte | L15: =IFERROR(IF(J15=I15, "Item não atualizado", "Item atualizado"), "Item não localizado") -> Item atualizado | N15: Cancelar Com o Suporte | O15: SEI não localizado | P15: j
A16: A.008-ARP.0008.05.2025.GOV.HGV.PE | B16: =IFERROR(__xludf.DUMMYFUNCTION("REGEXEXTRACT(A16, ""\.(?:GOV|EXT)\.([A-Z0-9\-]+)"") "),"HGV") -> HGV | C16: HOSPITAL REGIONAL DO AGRESTE DR.WALDEMIRO FERREIRA | D16: Adesão | E16: =IFERROR(__xludf.DUMMYFUNCTION("REGEXEXTRACT(A16, ""-(.*)"")"),"ARP.0008.05.2025.GOV.HGV.PE") -> ARP.0008.05.2025.GOV.HGV.PE | F16: Registro de Preços para o fornecimento eventual de MATERIAIS ESPECIAIS PARA ENDOSCOPIA | G16: NSADRE | H16: 45946 | I16: Cancelada | J16: =VLOOKUP(A16,'TODOS OS PROCESSOS ATUALIZADOS '!A:I,7,0) -> Cancelada | K16: Cancelado | L16: =IFERROR(IF(J16=I16, "Item não atualizado", "Item atualizado"), "Item não localizado") -> Item não atualizado | N16: Cancelado | O16: SEI não localizado
A17: A.031-ARP.0001.01.2025.GOV.HUOC.PE | B17: =IFERROR(__xludf.DUMMYFUNCTION("REGEXEXTRACT(A17, ""\.(?:GOV|EXT)\.([A-Z0-9\-]+)"") "),"HUOC") -> HUOC | C17: HOSPITAL REGIONAL DO AGRESTE DR.WALDEMIRO FERREIRA | D17: Adesão | E17: =IFERROR(__xludf.DUMMYFUNCTION("REGEXEXTRACT(A17, ""-(.*)"")"),"ARP.0001.01.2025.GOV.HUOC.PE") -> ARP.0001.01.2025.GOV.HUOC.PE | F17: Registro de Preços para o eventual fornecimento de ÓRTESES, PRÓTESES E MATERIAIS ESPECIAIS - OPME’S (TRAUMATO I), visando atender as necessidades do Hospital da Restauração. | G17: NFOCPO | H17: 45943 | I17: Concluído | J17: =VLOOKUP(A17,'TODOS OS PROCESSOS ATUALIZADOS '!A:I,7,0) -> Em configuração | K17: Concluído | L17: =IFERROR(IF(J17=I17, "Item não atualizado", "Item atualizado"), "Item não localizado") -> Item atualizado | N17: Em andamento | O17: Enviado ao GFIN | P17: 2300001213.000385/2025-15 | Q17: Finalizar com o nucleo
A18: A.007-ARP.0072.07.2025.GOV.HUOC.PE | B18: =IFERROR(__xludf.DUMMYFUNCTION("REGEXEXTRACT(A18, ""\.(?:GOV|EXT)\.([A-Z0-9\-]+)"") "),"HUOC") -> HUOC | C18: HOSPITAL REGIONAL DO AGRESTE DR.WALDEMIRO FERREIRA | D18: Adesão | E18: =IFERROR(__xludf.DUMMYFUNCTION("REGEXEXTRACT(A18, ""-(.*)"")"),"ARP.0072.07.2025.GOV.HUOC.PE") -> ARP.0072.07.2025.GOV.HUOC.PE | F18: Registro de Preços para o eventual fornecimento de MEDICAMENTOS CLÍNICOS GERAIS 6 - 18 ITENS - SEI: 0040609437.000009/2025-12 | H18: 45918 | I18: Concluído | J18: =VLOOKUP(A18,'TODOS OS PROCESSOS ATUALIZADOS '!A:I,7,0) -> Autorizada Sucesso | K18: Concluído | L18: =IFERROR(IF(J18=I18, "Item não atualizado", "Item atualizado"), "Item não localizado") -> Item atualizado | N18: Em andamento | O18: Enviado ao GFIN | P18: 2300001213.000376/2025-16
A19: A.007-ARP.0057.00.2025.GOV.HUOC.PE | B19: =IFERROR(__xludf.DUMMYFUNCTION("REGEXEXTRACT(A19, ""\.(?:GOV|EXT)\.([A-Z0-9\-]+)"") "),"HUOC") -> HUOC | C19: HOSPITAL REGIONAL DO AGRESTE DR.WALDEMIRO FERREIRA | D19: Adesão | E19: =IFERROR(__xludf.DUMMYFUNCTION("REGEXEXTRACT(A19, ""-(.*)"")"),"ARP.0057.00.2025.GOV.HUOC.PE") -> ARP.0057.00.2025.GOV.HUOC.PE | F19: Registro de Preços para o fornecimento eventual de MATERIAIS MÉDICOS HOSPITALARES - SONDA FOLEYS E CATETER INTRAVENOSO (SEI: 0040609912.000190/2024-15) | G19: NFOCPO | H19: 45925 | I19: Cancelada | J19: =VLOOKUP(A19,'TODOS OS PROCESSOS ATUALIZADOS '!A:I,7,0) -> Em configuração | K19: Cancelar Com o Suporte | L19: =IFERROR(IF(J19=I19, "Item não atualizado", "Item atualizado"), "Item não localizado") -> Item atualizado | N19: Cancelar Com o Suporte | O19: SEI não localizado
A20: A.007-ARP.0013.06.2025.GOV.HOF.PE | B20: =IFERROR(__xludf.DUMMYFUNCTION("REGEXEXTRACT(A20, ""\.(?:GOV|EXT)\.([A-Z0-9\-]+)"") "),"HOF") -> HOF | C20: HOSPITAL REGIONAL DO AGRESTE DR.WALDEMIRO FERREIRA | D20: Adesão | E20: =IFERROR(__xludf.DUMMYFUNCTION("REGEXEXTRACT(A20, ""-(.*)"")"),"ARP.0013.06.2025.GOV.HOF.PE") -> ARP.0013.06.2025.GOV.HOF.PE | F20: REGISTRO DE PREÇOS PARA O FORNECIMENTO DE DISPOSITIVOS MÉDICOS DO TIPO INSUMOS PARA OXIGENOTERAPIA, VISANDO ATENDER AS NECESSIDADES DO HOSPITAL OTÁVIO DE FREITAS. | G20: NAEN | H20: 45918 | I20: Cancelada | J20: =VLOOKUP(A20,'TODOS OS PROCESSOS ATUALIZADOS '!A:I,7,0) -> Em configuração | K20: Cancelar Com o Suporte | L20: =IFERROR(IF(J20=I20, "Item não atualizado", "Item atualizado"), "Item não localizado") -> Item atualizado | N20: Cancelar Com o Suporte | O20: SEI não localizado
A21: A.007-ARP.0008.05.2025.GOV.HGV.PE | B21: =IFERROR(__xludf.DUMMYFUNCTION("REGEXEXTRACT(A21, ""\.(?:GOV|EXT)\.([A-Z0-9\-]+)"") "),"HGV") -> HGV | C21: HOSPITAL REGIONAL DO AGRESTE DR.WALDEMIRO FERREIRA | D21: Adesão | E21: =IFERROR(__xludf.DUMMYFUNCTION("REGEXEXTRACT(A21, ""-(.*)"")"),"ARP.0008.05.2025.GOV.HGV.PE") -> ARP.0008.05.2025.GOV.HGV.PE | F21: Registro de Preços para o fornecimento eventual de MATERIAIS ESPECIAIS PARA ENDOSCOPIA | G21: NSADRE | H21: 45932 | I21: Cancelada | J21: =VLOOKUP(A21,'TODOS OS PROCESSOS ATUALIZADOS '!A:I,7,0) -> Cancelada | K21: Cancelado | L21: =IFERROR(IF(J21=I21, "Item não atualizado", "Item atualizado"), "Item não localizado") -> Item não atualizado | N21: Cancelado | O21: SEI não localizado
A22: A.007-ARP.0005.00.2025.GOV.FEAS.PE | B22: =IFERROR(__xludf.DUMMYFUNCTION("REGEXEXTRACT(A22, ""\.(?:GOV|EXT)\.([A-Z0-9\-]+)"") "),"FEAS") -> FEAS | C22: HOSPITAL REGIONAL DO AGRESTE DR.WALDEMIRO FERREIRA | D22: Adesão | E22: =IFERROR(__xludf.DUMMYFUNCTION("REGEXEXTRACT(A22, ""-(.*)"")"),"ARP.0005.00.2025.GOV.FEAS.PE") -> ARP.0005.00.2025.GOV.FEAS.PE | F22: Formação de Registro de Preços para o fornecimento eventual de MATERIAL DE LIMPEZA e MATERIAL HIGIENE PESSOAL visando atender as necessidades dos municípios que possam vir a ser afetados por desastre, e acolhida pela Secretária de Assistência Social, Combate à Fome e Políticas sobre Drogas por meio da Secretaria Executiva de Assistência Social, nos termos da legislação vigente e conforme as condições, especificações, quantidades e exigências contidas neste Termo de Referência | G22: NAMP | H22: 45923 | I22: Concluído | J22: =VLOOKUP(A22,'TODOS OS PROCESSOS ATUALIZADOS '!A:I,7,0) -> Autorizada Sucesso | K22: Concluído | L22: =IFERROR(IF(J22=I22, "Item não atualizado", "Item atualizado"), "Item não localizado") -> Item atualizado | N22: Em andamento | O22: Enviado ao JURIDICO | P22: 2300001213.000381/2025-29
A23: A.007-ARP.0001.00.2025.GOV.HR.PE | B23: =IFERROR(__xludf.DUMMYFUNCTION("REGEXEXTRACT(A23, ""\.(?:GOV|EXT)\.([A-Z0-9\-]+)"") "),"HR") -> HR | C23: HOSPITAL REGIONAL DO AGRESTE DR.WALDEMIRO FERREIRA | D23: Adesão | E23: =IFERROR(__xludf.DUMMYFUNCTION("REGEXEXTRACT(A23, ""-(.*)"")"),"ARP.0001.00.2025.GOV.HR.PE") -> ARP.0001.00.2025.GOV.HR.PE | F23: Registro de Preços para o eventual fornecimento de ÓRTESES, PRÓTESES E MATERIAIS ESPECIAIS - OPME’S (TRAUMATO I), visando atender as necessidades do Hospital da Restauração. | G23: NFOCPO | H23: 45943 | I23: Concluído | J23: =VLOOKUP(A23,'TODOS OS PROCESSOS ATUALIZADOS '!A:I,7,0) -> Autorizada Sucesso | K23: Concluído | L23: =IFERROR(IF(J23=I23, "Item não atualizado", "Item atualizado"), "Item não localizado") -> Item atualizado | N23: Em andamento | O23: Enviado a GCONTRATOS | P23: 2300002944.000002/2025-17
A24: A.006-ARP.0008.05.2025.GOV.HGV.PE | B24: =IFERROR(__xludf.DUMMYFUNCTION("REGEXEXTRACT(A24, ""\.(?:GOV|EXT)\.([A-Z0-9\-]+)"") "),"HGV") -> HGV | C24: HOSPITAL REGIONAL DO AGRESTE DR.WALDEMIRO FERREIRA | D24: Adesão | E24: =IFERROR(__xludf.DUMMYFUNCTION("REGEXEXTRACT(A24, ""-(.*)"")"),"ARP.0008.05.2025.GOV.HGV.PE") -> ARP.0008.05.2025.GOV.HGV.PE | F24: Registro de Preços para o fornecimento eventual de MATERIAIS ESPECIAIS PARA ENDOSCOPIA | G24: NSADRE | H24: 45925 | I24: Cancelada | J24: =VLOOKUP(A24,'TODOS OS PROCESSOS ATUALIZADOS '!A:I,7,0) -> Cancelada | K24: Cancelado | L24: =IFERROR(IF(J24=I24, "Item não atualizado", "Item atualizado"), "Item não localizado") -> Item não atualizado | N24: Cancelado | O24: SEI não localizado
A25: A.006-ARP.0005.00.2025.GOV.FEAS.PE | B25: =IFERROR(__xludf.DUMMYFUNCTION("REGEXEXTRACT(A25, ""\.(?:GOV|EXT)\.([A-Z0-9\-]+)"") "),"FEAS") -> FEAS | C25: HOSPITAL REGIONAL DO AGRESTE DR.WALDEMIRO FERREIRA | D25: Adesão | E25: =IFERROR(__xludf.DUMMYFUNCTION("REGEXEXTRACT(A25, ""-(.*)"")"),"ARP.0005.00.2025.GOV.FEAS.PE") -> ARP.0005.00.2025.GOV.FEAS.PE | F25: Formação de Registro de Preços para o fornecimento eventual de MATERIAL DE LIMPEZA e MATERIAL HIGIENE PESSOAL visando atender as necessidades dos municípios que possam vir a ser afetados por desastre, e acolhida pela Secretária de Assistência Social, Combate à Fome e Políticas sobre Drogas por meio da Secretaria Executiva de Assistência Social, nos termos da legislação vigente e conforme as condições, especificações, quantidades e exigências contidas neste Termo de Referência | G25: NAMP | H25: 45917 | I25: Cancelada | J25: =VLOOKUP(A25,'TODOS OS PROCESSOS ATUALIZADOS '!A:I,7,0) -> Em configuração | K25: Cancelar Com o Suporte | L25: =IFERROR(IF(J25=I25, "Item não atualizado", "Item atualizado"), "Item não localizado") -> Item atualizado | N25: Cancelar Com o Suporte | O25: SEI não localizado
A26: A.005-ARP.0011.00.2025.GOV.HAM.PE | B26: =IFERROR(__xludf.DUMMYFUNCTION("REGEXEXTRACT(A26, ""\.(?:GOV|EXT)\.([A-Z0-9\-]+)"") "),"HAM") -> HAM | C26: HOSPITAL REGIONAL DO AGRESTE DR.WALDEMIRO FERREIRA | D26: Adesão | E26: =IFERROR(__xludf.DUMMYFUNCTION("REGEXEXTRACT(A26, ""-(.*)"")"),"ARP.0011.00.2025.GOV.HAM.PE") -> ARP.0011.00.2025.GOV.HAM.PE | F26: REGISTRO DE PREÇOS PARA EVENTUAL FORNECIMENTO DE MATERIAL DE CONSUMO HOSPITALAR ( AQUISIÇÃO DE MATERIAL KIT DE CURATIVO P/ TERAPIA POR PRESSÃO NEGATIVA ) | G26: NFOCPO | H26: 45917 | I26: Concluído | J26: =VLOOKUP(A26,'TODOS OS PROCESSOS ATUALIZADOS '!A:I,7,0) -> Autorizada Sucesso | K26: Concluído | L26: =IFERROR(IF(J26=I26, "Item não atualizado", "Item atualizado"), "Item não localizado") -> Item atualizado | M26: Hannah | N26: Em andamento | O26: Enviado a GCONTRATOS | P26: 2300002541.000001/2025-05
A27: A.004-ARP.0010.05.2025.GOV.HAM.PE | B27: =IFERROR(__xludf.DUMMYFUNCTION("REGEXEXTRACT(A27, ""\.(?:GOV|EXT)\.([A-Z0-9\-]+)"") "),"HAM") -> HAM | C27: HOSPITAL REGIONAL DO AGRESTE DR.WALDEMIRO FERREIRA | D27: Adesão | E27: =IFERROR(__xludf.DUMMYFUNCTION("REGEXEXTRACT(A27, ""-(.*)"")"),"ARP.0010.05.2025.GOV.HAM.PE") -> ARP.0010.05.2025.GOV.HAM.PE | F27: Registro de Preços para o fornecimento eventual de material médico hospitalar destinado ao serviço de anestesia, visando atender as necessidades do Hospital Agamenon Magalhães | G27: NFOCPO | H27: 45916 | I27: Concluído | J27: =VLOOKUP(A27,'TODOS OS PROCESSOS ATUALIZADOS '!A:I,7,0) -> Autorizada Sucesso | K27: Concluído | L27: =IFERROR(IF(J27=I27, "Item não atualizado", "Item atualizado"), "Item não localizado") -> Item atualizado | M27: Hannah | N27: Em andamento | O27: Enviado a GCONTRATOS | P27: 2300001213.000369/2025-14
A28: A.003-ARP.0501.00.2025.EXT.HGJMM.RN | B28: =IFERROR(__xludf.DUMMYFUNCTION("REGEXEXTRACT(A28, ""\.(?:GOV|EXT)\.([A-Z0-9\-]+)"") "),"HGJMM") -> HGJMM | C28: HOSPITAL REGIONAL DO AGRESTE DR.WALDEMIRO FERREIRA | D28: Adesão | E28: =IFERROR(__xludf.DUMMYFUNCTION("REGEXEXTRACT(A28, ""-(.*)"")"),"ARP.0501.00.2025.EXT.HGJMM.RN") -> ARP.0501.00.2025.EXT.HGJMM.RN | F28: Aquisição de Medicamentos - ANTIMICROBIANOS , conforme condições e exigências estabelecidas neste instrumento. | G28: NFOCPO | H28: 45924 | I28: Cancelada | J28: =VLOOKUP(A28,'TODOS OS PROCESSOS ATUALIZADOS '!A:I,7,0) -> Cancelada por fim vigencia ATA | K28: Cancelado | L28: =IFERROR(IF(J28=I28, "Item não atualizado", "Item atualizado"), "Item não localizado") -> Item atualizado | N28: Cancelado | O28: SEI não localizado
A29: A.003-ARP.0118.05.2024.GOV.HUOC.PE | B29: =IFERROR(__xludf.DUMMYFUNCTION("REGEXEXTRACT(A29, ""\.(?:GOV|EXT)\.([A-Z0-9\-]+)"") "),"HUOC") -> HUOC | C29: HOSPITAL REGIONAL DO AGRESTE DR.WALDEMIRO FERREIRA | D29: Adesão | E29: =IFERROR(__xludf.DUMMYFUNCTION("REGEXEXTRACT(A29, ""-(.*)"")"),"ARP.0118.05.2024.GOV.HUOC.PE") -> ARP.0118.05.2024.GOV.HUOC.PE | F29: Registro de Preços para eventual fornecimento de MATERIAIS MÉDICOS HOSPITALARES PARA O SERVIÇO DE ENDOSCOPIA (SEI Nº0040609912.000069/2024-93) | H29: 45925 | I29: Concluído | J29: =VLOOKUP(A29,'TODOS OS PROCESSOS ATUALIZADOS '!A:I,7,0) -> Autorizada Sucesso | K29: Concluído | L29: =IFERROR(IF(J29=I29, "Item não atualizado", "Item atualizado"), "Item não localizado") -> Item atualizado | N29: Concluído | O29: Enviado ao NOF | P29: 2300001213.000404/2025-03
A30: A.003-ARP.0118.01.2024.GOV.HUOC.PE | B30: =IFERROR(__xludf.DUMMYFUNCTION("REGEXEXTRACT(A30, ""\.(?:GOV|EXT)\.([A-Z0-9\-]+)"") "),"HUOC") -> HUOC | C30: HOSPITAL REGIONAL DO AGRESTE DR.WALDEMIRO FERREIRA | D30: Adesão | E30: =IFERROR(__xludf.DUMMYFUNCTION("REGEXEXTRACT(A30, ""-(.*)"")"),"ARP.0118.01.2024.GOV.HUOC.PE") -> ARP.0118.01.2024.GOV.HUOC.PE | F30: Registro de Preços para eventual fornecimento de MATERIAIS MÉDICOS HOSPITALARES PARA O SERVIÇO DE ENDOSCOPIA (SEI Nº0040609912.000069/2024-93) | H30: 45925 | I30: Concluído | J30: =VLOOKUP(A30,'TODOS OS PROCESSOS ATUALIZADOS '!A:I,7,0) -> Autorizada Sucesso | K30: Concluído | L30: =IFERROR(IF(J30=I30, "Item não atualizado", "Item atualizado"), "Item não localizado") -> Item atualizado | N30: Concluído | O30: Enviado ao NOF | P30: 2300001213.000342/2025-21
A31: A.003-ARP.0073.05.2025.GOV.HUOC.PE | B31: =IFERROR(__xludf.DUMMYFUNCTION("REGEXEXTRACT(A31, ""\.(?:GOV|EXT)\.([A-Z0-9\-]+)"") "),"HUOC") -> HUOC | C31: HOSPITAL REGIONAL DO AGRESTE DR.WALDEMIRO FERREIRA | D31: Adesão | E31: =IFERROR(__xludf.DUMMYFUNCTION("REGEXEXTRACT(A31, ""-(.*)"")"),"ARP.0073.05.2025.GOV.HUOC.PE") -> ARP.0073.05.2025.GOV.HUOC.PE | F31: Registro de Preços para o eventual fornecimento de MEDICAMENTOS ANTINEOPLÁSICOS E ADJUVANTES (13 ITENS) (SEI: 0040609437.000263/2024-21) | H31: 45916 | I31: Concluído | J31: =VLOOKUP(A31,'TODOS OS PROCESSOS ATUALIZADOS '!A:I,7,0) -> Autorizada Sucesso | K31: Concluído | L31: =IFERROR(IF(J31=I31, "Item não atualizado", "Item atualizado"), "Item não localizado") -> Item atualizado | N31: Concluído | O31: Enviado ao NOF | P31: 2300001213.000362/2025-01
A32: A.003-ARP.0073.00.2025.GOV.FES-PE.PE | B32: =IFERROR(__xludf.DUMMYFUNCTION("REGEXEXTRACT(A32, ""\.(?:GOV|EXT)\.([A-Z0-9\-]+)"") "),"FES-PE") -> FES-PE | C32: HOSPITAL REGIONAL DO AGRESTE DR.WALDEMIRO FERREIRA | D32: Adesão | E32: =IFERROR(__xludf.DUMMYFUNCTION("REGEXEXTRACT(A32, ""-(.*)"")"),"ARP.0073.00.2025.GOV.FES-PE.PE") -> ARP.0073.00.2025.GOV.FES-PE.PE | F32: Registro de Preços para o fornecimento eventual de Dispositivos Médicos do tipo Materiais Médicos (Indicadores, cera, e cimento cirúrgico), conforme especificações e quantitativos previstos no Termo de Referência, visando atender as necessidades dos hospitais e estabelecimentos vinculados à Secretaria Estadual de Saúde de Pernambuco | G32: NFOCPO | H32: 45946 | I32: Concluído | J32: =VLOOKUP(A32,'TODOS OS PROCESSOS ATUALIZADOS '!A:I,7,0) -> Autorizada Sucesso | K32: Concluído | L32: =IFERROR(IF(J32=I32, "Item não atualizado", "Item atualizado"), "Item não localizado") -> Item atualizado | N32: Concluído | O32: Enviado ao NOF | P32: 2300001213.000239/2025-81
A33: A.003-ARP.0044.04.2025.GOV.FES-PE.PE | B33: =IFERROR(__xludf.DUMMYFUNCTION("REGEXEXTRACT(A33, ""\.(?:GOV|EXT)\.([A-Z0-9\-]+)"") "),"FES-PE") -> FES-PE | C33: HOSPITAL REGIONAL DO AGRESTE DR.WALDEMIRO FERREIRA | D33: Adesão | E33: =IFERROR(__xludf.DUMMYFUNCTION("REGEXEXTRACT(A33, ""-(.*)"")"),"ARP.0044.04.2025.GOV.FES-PE.PE") -> ARP.0044.04.2025.GOV.FES-PE.PE | F33: Formação de Registro de Preços para o fornecimento eventual de dispositivos médicos do Tipo DRENOS visando atender as necessidades dos hospitais e estabelecimentos vinculados à Secretaria Estadual de Saúde de Pernambuco, conforme as condições, especificações, quantidades e exigências contidas no Termo de Referência | H33: 45924 | I33: Cancelada | J33: =VLOOKUP(A33,'TODOS OS PROCESSOS ATUALIZADOS '!A:I,7,0) -> Cancelada | K33: Cancelado | L33: =IFERROR(IF(J33=I33, "Item não atualizado", "Item atualizado"), "Item não localizado") -> Item não atualizado | N33: Cancelado | O33: SEI não localizado
A34: A.003-ARP.0009.01.2025.EXT.HMAR.PE | B34: =IFERROR(__xludf.DUMMYFUNCTION("REGEXEXTRACT(A34, ""\.(?:GOV|EXT)\.([A-Z0-9\-]+)"") "),"HMAR") -> HMAR | C34: HOSPITAL REGIONAL DO AGRESTE DR.WALDEMIRO FERREIRA | D34: Adesão | E34: =IFERROR(__xludf.DUMMYFUNCTION("REGEXEXTRACT(A34, ""-(.*)"")"),"ARP.0009.01.2025.EXT.HMAR.PE") -> ARP.0009.01.2025.EXT.HMAR.PE | F34: Registro de preços para eventual aquisição de produtos para saúde - MMH4 , visando atenderas necessidades do Hospital do Hospital Militar de Área de Recife (HMAR) | H34: 45923 | I34: Cancelada | J34: =VLOOKUP(A34,'TODOS OS PROCESSOS ATUALIZADOS '!A:I,7,0) -> Cancelada | K34: Cancelado | L34: =IFERROR(IF(J34=I34, "Item não atualizado", "Item atualizado"), "Item não localizado") -> Item não atualizado | N34: Cancelado | O34: SEI não localizado
A35: A.003-ARP.0008.02.2025.GOV.HGV.PE | B35: =IFERROR(__xludf.DUMMYFUNCTION("REGEXEXTRACT(A35, ""\.(?:GOV|EXT)\.([A-Z0-9\-]+)"") "),"HGV") -> HGV | C35: HOSPITAL REGIONAL DO AGRESTE DR.WALDEMIRO FERREIRA | D35: Adesão | E35: =IFERROR(__xludf.DUMMYFUNCTION("REGEXEXTRACT(A35, ""-(.*)"")"),"ARP.0008.02.2025.GOV.HGV.PE") -> ARP.0008.02.2025.GOV.HGV.PE | F35: Registro de Preços para o fornecimento eventual de MATERIAIS ESPECIAIS PARA ENDOSCOPIA | H35: 45917 | I35: Concluído | J35: =VLOOKUP(A35,'TODOS OS PROCESSOS ATUALIZADOS '!A:I,7,0) -> Autorizada Sucesso | K35: Concluído | L35: =IFERROR(IF(J35=I35, "Item não atualizado", "Item atualizado"), "Item não localizado") -> Item atualizado | N35: Em andamento | O35: Enviado ao GFIN | P35: 2300001213.000313/2025-60
A36: A.003-ARP.0006.03.2025.GOV.PROCAPE.PE | B36: =IFERROR(__xludf.DUMMYFUNCTION("REGEXEXTRACT(A36, ""\.(?:GOV|EXT)\.([A-Z0-9\-]+)"") "),"PROCAPE") -> PROCAPE | C36: HOSPITAL REGIONAL DO AGRESTE DR.WALDEMIRO FERREIRA | D36: Adesão | E36: =IFERROR(__xludf.DUMMYFUNCTION("REGEXEXTRACT(A36, ""-(.*)"")"),"ARP.0006.03.2025.GOV.PROCAPE.PE") -> ARP.0006.03.2025.GOV.PROCAPE.PE | F36: REGISTRO DE PREÇOS PARA EVENTUAL FORNECIMENTO DE MATERIAL DE CONSUMO HOSPITALAR (MEDICAMENTOS) | H36: 45929 | I36: Concluído | J36: =VLOOKUP(A36,'TODOS OS PROCESSOS ATUALIZADOS '!A:I,7,0) -> Autorizada Sucesso | K36: Concluído | L36: =IFERROR(IF(J36=I36, "Item não atualizado", "Item atualizado"), "Item não localizado") -> Item atualizado | N36: Concluído | O36: Enviado ao NOF | P36: 2300001213.000119/2025-84
A37: A.002-ARP.1190.00.2025.EXT.158552.PB | B37: =IFERROR(__xludf.DUMMYFUNCTION("REGEXEXTRACT(A37, ""\.(?:GOV|EXT)\.([A-Z0-9\-]+)"") "),"158552") -> 158552 | C37: HOSPITAL REGIONAL DO AGRESTE DR.WALDEMIRO FERREIRA | D37: Adesão | E37: =IFERROR(__xludf.DUMMYFUNCTION("REGEXEXTRACT(A37, ""-(.*)"")"),"ARP.1190.00.2025.EXT.158552.PB") -> ARP.1190.00.2025.EXT.158552.PB | F37: MIDAZOLAM 1 mg/mL (5 mg) solução injetável (ampola 5 mL). | H37: 45917 | I37: Concluído | J37: =VLOOKUP(A37,'TODOS OS PROCESSOS ATUALIZADOS '!A:I,7,0) -> Autorizada Integrado | K37: Concluído | L37: =IFERROR(IF(J37=I37, "Item não atualizado", "Item atualizado"), "Item não localizado") -> Item atualizado | N37: Concluído | O37: Enviado ao NOF | P37: 2300001213.000237/2025-92
A38: A.002-ARP.0118.05.2024.GOV.HUOC.PE | B38: =IFERROR(__xludf.DUMMYFUNCTION("REGEXEXTRACT(A38, ""\.(?:GOV|EXT)\.([A-Z0-9\-]+)"") "),"HUOC") -> HUOC | C38: HOSPITAL REGIONAL DO AGRESTE DR.WALDEMIRO FERREIRA | D38: Adesão | E38: =IFERROR(__xludf.DUMMYFUNCTION("REGEXEXTRACT(A38, ""-(.*)"")"),"ARP.0118.05.2024.GOV.HUOC.PE") -> ARP.0118.05.2024.GOV.HUOC.PE | F38: Registro de Preços para eventual fornecimento de MATERIAIS MÉDICOS HOSPITALARES PARA O SERVIÇO DE ENDOSCOPIA (SEI Nº0040609912.000069/2024-93) | H38: 45923 | I38: Concluído | J38: =VLOOKUP(A38,'TODOS OS PROCESSOS ATUALIZADOS '!A:I,7,0) -> Autorizada Sucesso | K38: Concluído | L38: =IFERROR(IF(J38=I38, "Item não atualizado", "Item atualizado"), "Item não localizado") -> Item atualizado | N38: Concluído | O38: Enviado ao NOF | P38: 2300001213.000341/2025-87
A39: A.002-ARP.0102.01.2025.GOV.HUOC.PE | B39: =IFERROR(__xludf.DUMMYFUNCTION("REGEXEXTRACT(A39, ""\.(?:GOV|EXT)\.([A-Z0-9\-]+)"") "),"HUOC") -> HUOC | C39: HOSPITAL REGIONAL DO AGRESTE DR.WALDEMIRO FERREIRA | D39: Adesão | E39: =IFERROR(__xludf.DUMMYFUNCTION("REGEXEXTRACT(A39, ""-(.*)"")"),"ARP.0102.01.2025.GOV.HUOC.PE") -> ARP.0102.01.2025.GOV.HUOC.PE | F39: Registro de Preços para o eventual fornecimento de GRAMPEADORES E CARGAR LINEARES E CIRCULARES (SEI Nº 0040609912.000126/2024-34) | G39: NAMP | H39: 45943 | I39: Concluído | J39: =VLOOKUP(A39,'TODOS OS PROCESSOS ATUALIZADOS '!A:I,7,0) -> Autorizada Sucesso | K39: Concluído | L39: =IFERROR(IF(J39=I39, "Item não atualizado", "Item atualizado"), "Item não localizado") -> Item atualizado | N39: Em andamento | O39: Enviado ao GFIN | P39: 2300001213.000398/2025-86
A40: A.002-ARP.0068.04.2025.GOV.FES-PE.PE | B40: =IFERROR(__xludf.DUMMYFUNCTION("REGEXEXTRACT(A40, ""\.(?:GOV|EXT)\.([A-Z0-9\-]+)"") "),"FES-PE") -> FES-PE | C40: HOSPITAL REGIONAL DO AGRESTE DR.WALDEMIRO FERREIRA | D40: Adesão | E40: =IFERROR(__xludf.DUMMYFUNCTION("REGEXEXTRACT(A40, ""-(.*)"")"),"ARP.0068.04.2025.GOV.FES-PE.PE") -> ARP.0068.04.2025.GOV.FES-PE.PE | F40: FORMAÇÃO DE REGISTRO DE PREÇOS PARA O FORNECIMENTO DE DISPOSITIVOS MÉDICOS, DO TIPO INSUMOS PARA OSTOMIA, VISANDO ATENDER AS NECESSIDADES DOS HOSPITAIS E ESTABELECIMENTOS VINCULADOS À SECRETARIA ESTADUAL DE SAÚDE DE PERNAMBUCO | G40: NFOCPO | H40: 45918 | I40: Cancelada | J40: =VLOOKUP(A40,'TODOS OS PROCESSOS ATUALIZADOS '!A:I,7,0) -> Em configuração | K40: Cancelar Com o Suporte | L40: =IFERROR(IF(J40=I40, "Item não atualizado", "Item atualizado"), "Item não localizado") -> Item atualizado | N40: Cancelar Com o Suporte | O40: SEI não localizado
...

Sheet PROCESSOS CONCLUIDOS
A1: Número da solicitação | B1: Unidade gestora | C1: Tipo da solicitação | D1: Número da ata | E1: Objeto | F1: Data de solicitação | G1: Situação | H1: SEI | I1: ENCAMINHADO / SETOR | J1: DATA DO ENCAMINHAMENTO | K1: STATUS | L1: VALOR
A2: C.002-ARP.0099.00.2025.GOV.FES-PE.PE | B2: HOSPITAL REGIONAL DO AGRESTE DR.WALDEMIRO FERREIRA | C2: Consumo | D2: ARP.0099.00.2025.GOV.FES-PE.PE | E2: Formação de Registro de Preços para o fornecimento de Dispositivos Médicos do tipo Disco para Antibiograma visando atender as necessidades dos hospitais e estabelecimentos vinculados à Secretaria Estadual de Saúde de Pernambuco | F2: 45940 | G2: Autorizada Sucesso | H2: 2300001209.000078/2025-95 | I2: GCONTRATOS | J2: 45943 | K2: AGUARDANDO EMPENHO | L2: 4139.77
A3: C.015-ARPC.0039.00.2025.GOV.SAD.PE | B3: HOSPITAL REGIONAL DO AGRESTE DR.WALDEMIRO FERREIRA | C3: Consumo | D3: ARPC.0039.00.2025.GOV.SAD.PE | E3: Registro de Preços para o fornecimento eventual de material de higiene pessoal, visando atender as necessidades dos órgãos da Administração Direta, dos Fundos Especiais Autarquias e Fundações Públicas integrantes do Poder Executivo do Estado de Pernambuco | F3: 45937 | G3: Autorizada Sucesso | H3: 2300002544.000078/2025-47 | I3: GCONTRATOS | J3: 45952
A4: C.007-ARP.0049.03.2025.GOV.FES-PE.PE | B4: HOSPITAL REGIONAL DO AGRESTE DR.WALDEMIRO FERREIRA | C4: Consumo | D4: ARP.0049.03.2025.GOV.FES-PE.PE | E4: Formação de Registro de Preços para o fornecimento eventual de Medicamentos Comprimidos Grupo 4 visando atender as necessidades dos hospitais e estabelecimentos vinculados à Secretaria Estadual de Saúde de Pernambuco | F4: 45916 | G4: Autorizada Sucesso | H4: 2300001213.000413/2025-96 | I4: GCONTRATOS | J4: 22/102025
A5: C.008-ARP.0049.01.2025.GOV.FES-PE.PE | B5: HOSPITAL REGIONAL DO AGRESTE DR.WALDEMIRO FERREIRA | C5: Consumo | D5: ARP.0049.01.2025.GOV.FES-PE.PE | E5: Formação de Registro de Preços para o fornecimento eventual de Medicamentos Comprimidos Grupo 4 visando atender as necessidades dos hospitais e estabelecimentos vinculados à Secretaria Estadual de Saúde de Pernambuco | F5: 45911 | G5: Autorizada Sucesso | H5: 2300001213.000408/2025-83 | I5: GCONTRATOS | J5: 45952
A6: C.011-ARP.0049.04.2025.GOV.FES-PE.PE | B6: HOSPITAL REGIONAL DO AGRESTE DR.WALDEMIRO FERREIRA | C6: Consumo | D6: ARP.0049.04.2025.GOV.FES-PE.PE | E6: Formação de Registro de Preços para o fornecimento eventual de Medicamentos Comprimidos Grupo 4 visando atender as necessidades dos hospitais e estabelecimentos vinculados à Secretaria Estadual de Saúde de Pernambuco | F6: 45911 | G6: Autorizada Sucesso | H6: 2300001213.000406/2025-94 | I6: GCONTRATOS | J6: 45952
A7: C.011-ARP.0008.01.2025.GOV.HAM.PE | B7: HOSPITAL REGIONAL DO AGRESTE DR.WALDEMIRO FERREIRA | C7: Consumo | D7: ARP.0008.01.2025.GOV.HAM.PE | E7: Formação de Registro de Preços para o fornecimento eventual de solução parenteral por um período de 12 meses, visando atender as necessidades do Hospital Agamenon Magalhães | F7: 45908 | G7: Autorizada Sucesso | H7: Não Localizado
A8: C.014-ARP.0067.01.2025.GOV.FES-PE.PE | B8: HOSPITAL REGIONAL DO AGRESTE DR.WALDEMIRO FERREIRA | C8: Consumo | D8: ARP.0067.01.2025.GOV.FES-PE.PE | E8: FORMAÇÃO DE REGISTRO DE PREÇOS PARA O FORNECIMENTO DE DISPOSITIVOS MÉDICOS, DO TIPO MATERIAIS MÉDICO HOSPITALARES (GRUPO 8), VISANDO ATENDER AS NECESSIDADES DOS HOSPITAIS E ESTABELECIMENTOS VINCULADOS À SECRETARIA ESTADUAL DE SAÚDE DE PERNAMBUCO | F8: 45905 | G8: Autorizada Sucesso | H8: Não Localizado
A9: C.006-ARP.0077.01.2025.GOV.FES-PE.PE | B9: HOSPITAL REGIONAL DO AGRESTE DR.WALDEMIRO FERREIRA | C9: Consumo | D9: ARP.0077.01.2025.GOV.FES-PE.PE | E9: Registro de Preços para Fornecimento Eventual de Dispositivos Médicos do tipo: Antissépticos, Desinfetantes e Saneantes – Grupo 2 | F9: 45904 | G9: Autorizada Sucesso | H9: Não Localizado
A10: C.011-ARP.0044.04.2025.GOV.FES-PE.PE | B10: HOSPITAL REGIONAL DO AGRESTE DR.WALDEMIRO FERREIRA | C10: Consumo | D10: ARP.0044.04.2025.GOV.FES-PE.PE | E10: Formação de Registro de Preços para o fornecimento eventual de dispositivos médicos do Tipo DRENOS visando atender as necessidades dos hospitais e estabelecimentos vinculados à Secretaria Estadual de Saúde de Pernambuco, conforme as condições, especificações, quantidades e exigências contidas no Termo de Referência | F10: 45904 | G10: Autorizada Sucesso | H10: Não Localizado
A11: C.009-ARP.0044.02.2025.GOV.FES-PE.PE | B11: HOSPITAL REGIONAL DO AGRESTE DR.WALDEMIRO FERREIRA | C11: Consumo | D11: ARP.0044.02.2025.GOV.FES-PE.PE | E11: Formação de Registro de Preços para o fornecimento eventual de dispositivos médicos do Tipo DRENOS visando atender as necessidades dos hospitais e estabelecimentos vinculados à Secretaria Estadual de Saúde de Pernambuco, conforme as condições, especificações, quantidades e exigências contidas no Termo de Referência | F11: 45904 | G11: Autorizada Integrado | H11: Não Localizado
A12: C.002-ARP.0022.02.2024.GOV.HOF.PE | B12: HOSPITAL REGIONAL DO AGRESTE DR.WALDEMIRO FERREIRA | C12: Consumo | D12: ARP.0022.02.2024.GOV.HOF.PE | E12: FORMAÇÃO DE REGISTRO DE PREÇOS PARA O FORNECIMENTO EVENTUAL DE INSUMOS PARA O SERVIÇO DE CIRURGIA TORÁCICA VISANDO ATENDER AS NECESSIDADES DO HOSPITAL OTÁVIO DE FREITAS E HOSPITAL REGIONAL DO AGRESTE. | F12: 45902 | G12: Autorizada Sucesso | H12: Não Localizado
A13: C.004-ARP.0001.00.2024.FES-PE.PE | B13: HOSPITAL REGIONAL DO AGRESTE DR.WALDEMIRO FERREIRA | C13: Consumo | D13: ARP.0001.00.2024.FES-PE.PE | E13: Formação de Registro de Preços para o fornecimento eventual de Água Mineral sem gás, visando atender as necessidades da Secretaria Estadual de Saúde de Pernambuco e dos hospitais da Região Metropolitana do Recife (RMR) e das cidades de Caruaru, Garanhuns e Serra Talhada. | F13: 45898 | G13: Autorizada Sucesso | H13: Não Localizado
A14: C.023-ARP.0070.03.2025.GOV.FES-PE.PE | B14: HOSPITAL REGIONAL DO AGRESTE DR.WALDEMIRO FERREIRA | C14: Consumo | D14: ARP.0070.03.2025.GOV.FES-PE.PE | E14: Formação de Registro de Preços para o fornecimento eventual de medicamentos (INJETÁVEIS GRUPO 10) visando atender as necessidades dos hospitais e estabelecimentos vinculados à Secretaria Estadual de Saúde de Pernambuco | F14: 45891 | G14: Autorizada Sucesso | H14: Não Localizado
A15: C.004-ARP.0079.01.2025.GOV.FES-PE.PE | B15: HOSPITAL REGIONAL DO AGRESTE DR.WALDEMIRO FERREIRA | C15: Consumo | D15: ARP.0079.01.2025.GOV.FES-PE.PE | E15: Registro de Preços para a eventual aquisição de Material Médico Hospitalar - MMH (grupo 01) | F15: 45891 | G15: Autorizada Sucesso | H15: Não Localizado
A16: C.004-ARP.0079.00.2025.GOV.FES-PE.PE | B16: HOSPITAL REGIONAL DO AGRESTE DR.WALDEMIRO FERREIRA | C16: Consumo | D16: ARP.0079.00.2025.GOV.FES-PE.PE | E16: Registro de Preços para a eventual aquisição de Material Médico Hospitalar - MMH (grupo 01) | F16: 45891 | G16: Autorizada Sucesso | H16: Não Localizado
A17: C.010-ARP.0008.01.2025.GOV.HAM.PE | B17: HOSPITAL REGIONAL DO AGRESTE DR.WALDEMIRO FERREIRA | C17: Consumo | D17: ARP.0008.01.2025.GOV.HAM.PE | E17: Formação de Registro de Preços para o fornecimento eventual de solução parenteral por um período de 12 meses, visando atender as necessidades do Hospital Agamenon Magalhães | F17: 45882 | G17: Autorizada Sucesso | H17: Não Localizado
A18: C.007-ARP.0079.14.2025.GOV.FES-PE.PE | B18: HOSPITAL REGIONAL DO AGRESTE DR.WALDEMIRO FERREIRA | C18: Consumo | D18: ARP.0079.14.2025.GOV.FES-PE.PE | E18: Registro de Preços para a eventual aquisição de Material Médico Hospitalar - MMH (grupo 01) | F18: 45880 | G18: Autorizada Sucesso | H18: Não Localizado
... A21: C.005-ARP.0068.00.2025.GOV.FES-PE.PE | B21: HOSPITAL REGIONAL DO AGRESTE DR.WALDEMIRO FERREIRA | C21: Consumo | D21: ARP.0068.00.2025.GOV.FES-PE.PE | E21: FORMAÇÃO DE REGISTRO DE PREÇOS PARA O FORNECIMENTO DE DISPOSITIVOS MÉDICOS, DO TIPO INSUMOS PARA OSTOMIA, VISANDO ATENDER AS NECESSIDADES DOS HOSPITAIS E ESTABELECIMENTOS VINCULADOS À SECRETARIA ESTADUAL DE SAÚDE DE PERNAMBUCO | F21: 45874 | G21: Autorizada Sucesso | H21: Não Localizado
A22: C.002-ARP.0011.03.2025.GOV.HGV.PE | B22: HOSPITAL REGIONAL DO AGRESTE DR.WALDEMIRO FERREIRA | C22: Consumo | D22: ARP.0011.03.2025.GOV.HGV.PE | E22: Formação de Registro de Preços para o fornecimento eventual de SMS - EMBALAGENS DESCARTÁVEIS PARA ESTERILIZAÇÃO visando atender a demanda do Hospital Getúlio Vargas conforme condições, especificações, quantidades e exigências contidas neste Termo de Referência. | F22: 45874 | G22: Autorizada Sucesso | H22: 2300001213.000317/2025-48 | I22: juridico | J22: 45960
A23: C.003-ARP.0079.04.2025.GOV.FES-PE.PE | B23: HOSPITAL REGIONAL DO AGRESTE DR.WALDEMIRO FERREIRA | C23: Consumo | D23: ARP.0079.04.2025.GOV.FES-PE.PE | E23: Registro de Preços para a eventual aquisição de Material Médico Hospitalar - MMH (grupo 01) | F23: 45869 | G23: Autorizada Sucesso | H23: 2300001213.000312/2025-15 | I23: juridico | J23: 45960
A24: C.012-ARP.0044.06.2025.GOV.FES-PE.PE | B24: HOSPITAL REGIONAL DO AGRESTE DR.WALDEMIRO FERREIRA | C24: Consumo | D24: ARP.0044.06.2025.GOV.FES-PE.PE | E24: Formação de Registro de Preços para o fornecimento eventual de dispositivos médicos do Tipo DRENOS visando atender as necessidades dos hospitais e estabelecimentos vinculados à Secretaria Estadual de Saúde de Pernambuco, conforme as condições, especificações, quantidades e exigências contidas no Termo de Referência | F24: 45863 | G24: Autorizada Sucesso | H24: Não Localizado
A25: C.014-ARP.0016.03.2025.GOV.FES-PE.PE | B25: HOSPITAL REGIONAL DO AGRESTE DR.WALDEMIRO FERREIRA | C25: Consumo | D25: ARP.0016.03.2025.GOV.FES-PE.PE | E25: Registro de Preços para o fornecimento eventual de medicamentos do tipo COMPRIMIDOS (Grupo 05 | F25: 45862 | G25: Autorizada Sucesso
A26: C.017-ARP.0009.00.2025.GOV.FES-PE.PE | B26: HOSPITAL REGIONAL DO AGRESTE DR.WALDEMIRO FERREIRA | C26: Consumo | D26: ARP.0009.00.2025.GOV.FES-PE.PE | E26: Registro de Preços para aquisição de Material Médico Hospitalar - Luvas (Unificado) | F26: 45861 | G26: Autorizada Sucesso | H26: 2300002544.000067/2025-67 | I26: ORDEM DE FORNECIMENTO | J26: 45933
A27: C.003-ARP.0011.02.2025.GOV.HGV.PE | B27: HOSPITAL REGIONAL DO AGRESTE DR.WALDEMIRO FERREIRA | C27: Consumo | D27: ARP.0011.02.2025.GOV.HGV.PE | E27: Formação de Registro de Preços para o fornecimento eventual de SMS - EMBALAGENS DESCARTÁVEIS PARA ESTERILIZAÇÃO visando atender a demanda do Hospital Getúlio Vargas conforme condições, especificações, quantidades e exigências contidas neste Termo de Referência. | F27: 45860 | G27: Autorizada Sucesso | H27: Não Localizado
A28: C.002-ARP.0077.00.2025.GOV.FES-PE.PE | B28: HOSPITAL REGIONAL DO AGRESTE DR.WALDEMIRO FERREIRA | C28: Consumo | D28: ARP.0077.00.2025.GOV.FES-PE.PE | E28: Registro de Preços para Fornecimento Eventual de Dispositivos Médicos do tipo: Antissépticos, Desinfetantes e Saneantes – Grupo 2 | F28: 45859 | G28: Autorizada Sucesso | H28: Não Localizado
A29: C.012-ARP.0053.02.2025.GOV.FES-PE.PE | B29: HOSPITAL REGIONAL DO AGRESTE DR.WALDEMIRO FERREIRA | C29: Consumo | D29: ARP.0053.02.2025.GOV.FES-PE.PE | E29: Formação de Ata de Registro de Preços para o fornecimento eventual de Dispositivos Médicos do Tipo: Diversos visando atender as necessidades dos hospitais e estabelecimentos da rede estadual de saúde de Pernambuco | F29: 45853 | G29: Autorizada Sucesso | H29: Não Localizado
A30: C.009-ARP.0008.01.2025.GOV.HAM.PE | B30: HOSPITAL REGIONAL DO AGRESTE DR.WALDEMIRO FERREIRA | C30: Consumo | D30: ARP.0008.01.2025.GOV.HAM.PE | E30: Formação de Registro de Preços para o fornecimento eventual de solução parenteral por um período de 12 meses, visando atender as necessidades do Hospital Agamenon Magalhães | F30: 45849 | G30: Autorizada Sucesso | H30: Não Localizado
A31: C.016-ARP.0070.03.2025.GOV.FES-PE.PE | B31: HOSPITAL REGIONAL DO AGRESTE DR.WALDEMIRO FERREIRA | C31: Consumo | D31: ARP.0070.03.2025.GOV.FES-PE.PE | E31: Formação de Registro de Preços para o fornecimento eventual de medicamentos (INJETÁVEIS GRUPO 10) visando atender as necessidades dos hospitais e estabelecimentos vinculados à Secretaria Estadual de Saúde de Pernambuco | F31: 45848 | G31: Autorizada Sucesso | H31: Não Localizado
A32: C.002-ARP.0011.01.2025.GOV.HGV.PE | B32: HOSPITAL REGIONAL DO AGRESTE DR.WALDEMIRO FERREIRA | C32: Consumo | D32: ARP.0011.01.2025.GOV.HGV.PE | E32: Formação de Registro de Preços para o fornecimento eventual de SMS - EMBALAGENS DESCARTÁVEIS PARA ESTERILIZAÇÃO visando atender a demanda do Hospital Getúlio Vargas conforme condições, especificações, quantidades e exigências contidas neste Termo de Referência. | F32: 45838 | G32: Autorizada Sucesso | H32: 2300001213.000258/2025-16 | I32: ORDEM DE FORNECIMENTO | J32: 45909
A33: C.005-ARP.0087.02.2024.GOV.CISAM.PE | B33: HOSPITAL REGIONAL DO AGRESTE DR.WALDEMIRO FERREIRA | C33: Consumo | D33: ARP.0087.02.2024.GOV.CISAM.PE | E33: REGISTRO DE PREÇOS PARA FORNECIMENTO EVENTUAL DE MATERIAIS MÉDICO-HOSPITALARES (DIVERSOS), VISANDO ATENDER AS NECESSIDADES DO CISAM/UPE E DEMAIS ÓRGÃO PARTICIPANTES. | F33: 45833 | G33: Autorizada Sucesso | H33: 2300001213.000254/2025-20 | I33: nfo | J33: 45959
A34: C.002-ARP.0006.03.2025.GOV.CISAM.PE | B34: HOSPITAL REGIONAL DO AGRESTE DR.WALDEMIRO FERREIRA | C34: Consumo | D34: ARP.0006.03.2025.GOV.CISAM.PE | E34: REGISTRO DE PREÇOS PARA O FORNECIMENTO EVENTUAL DE MATERIAIS MÉDICO-HOSPITALARES (SERINGA DESCARTÁVEL), VISANDO ATENDER AS NECESSIDADES DO CISAM/UPE E DEMAIS ÓRGÃOS PARTICIPANTES | F34: 45826 | G34: Autorizada Sucesso | H34: 2300001213.000255/2025-74 | I34: nfo | J34: 45959
A35: C.007-ARP.0008.01.2025.GOV.HAM.PE | B35: HOSPITAL REGIONAL DO AGRESTE DR.WALDEMIRO FERREIRA | C35: Consumo | D35: ARP.0008.01.2025.GOV.HAM.PE | E35: Formação de Registro de Preços para o fornecimento eventual de solução parenteral por um período de 12 meses, visando atender as necessidades do Hospital Agamenon Magalhães | F35: 45824 | G35: Autorizada Sucesso | H35: Não Localizado
A36: C.028-ARP.0064.02.2024.GOV.FES-PE.PE | B36: HOSPITAL REGIONAL DO AGRESTE DR.WALDEMIRO FERREIRA | C36: Consumo | D36: ARP.0064.02.2024.GOV.FES-PE.PE | E36: PREGÃO ELETRÔNICO PARA FORMAÇÃO DE REGISTRO DE PREÇOS PARA A EVENTUAL FORNECIMENTO DE MEDICAMENTOS INJETÁVEIS (GRUPO 04) VISANDO ATENDER A DEMANDA DOS HOSPITAIS E ESTABELECIMENTOS DA REDE ESTADUAL DE SAÚDE DE PERNAMBUCO. | F36: 45819 | G36: Autorizada Sucesso | H36: Não Localizado
A37: C.004-ARP.0073.01.2025.GOV.FES-PE.PE | B37: HOSPITAL REGIONAL DO AGRESTE DR.WALDEMIRO FERREIRA | C37: Consumo | D37: ARP.0073.01.2025.GOV.FES-PE.PE | E37: Registro de Preços para o fornecimento eventual de Dispositivos Médicos do tipo Materiais Médicos (Indicadores, cera, e cimento cirúrgico), conforme especificações e quantitativos previstos no Termo de Referência, visando atender as necessidades dos hospitais e estabelecimentos vinculados à Secretaria Estadual de Saúde de Pernambuco | F37: 45818 | G37: Autorizada Sucesso | H37: Não Localizado
A38: C.004-ARP.0073.00.2025.GOV.FES-PE.PE | B38: HOSPITAL REGIONAL DO AGRESTE DR.WALDEMIRO FERREIRA | C38: Consumo | D38: ARP.0073.00.2025.GOV.FES-PE.PE | E38: Registro de Preços para o fornecimento eventual de Dispositivos Médicos do tipo Materiais Médicos (Indicadores, cera, e cimento cirúrgico), conforme especificações e quantitativos previstos no Termo de Referência, visando atender as necessidades dos hospitais e estabelecimentos vinculados à Secretaria Estadual de Saúde de Pernambuco | F38: 45818 | G38: Autorizada Sucesso | H38: Não Localizado
A39: C.005-ARP.0045.00.2025.GOV.FES-PE.PE | B39: HOSPITAL REGIONAL DO AGRESTE DR.WALDEMIRO FERREIRA | C39: Consumo | D39: ARP.0045.00.2025.GOV.FES-PE.PE | E39: Registro de Preços para o fornecimento eventual de Medicamentos Comprimidos (Grupo 03), visando atender as necessidades dos hospitais e estabelecimentos vinculados à Secretaria Estadual de Saúde de Pernambuco. | F39: 45813 | G39: Autorizada Sucesso | H39: Não Localizado
A40: C.012-ARP.0070.03.2025.GOV.FES-PE.PE | B40: HOSPITAL REGIONAL DO AGRESTE DR.WALDEMIRO FERREIRA | C40: Consumo | D40: ARP.0070.03.2025.GOV.FES-PE.PE | E40: Formação de Registro de Preços para o fornecimento eventual de medicamentos (INJETÁVEIS GRUPO 10) visando atender as necessidades dos hospitais e estabelecimentos vinculados à Secretaria Estadual de Saúde de Pernambuco | F40: 45812 | G40: Autorizada Sucesso | H40: Não Localizado
A41: C.022-ARP.0015.06.2025.GOV.FES-PE.PE | B41: HOSPITAL REGIONAL DO AGRESTE DR.WALDEMIRO FERREIRA | C41: Consumo | D41: ARP.0015.06.2025.GOV.FES-PE.PE | E41: Formação de Registro de Preços para o fornecimento eventual de medicamentos visando atender as necessidades dos hospitais e estabelecimentos vinculados à Secretaria Estadual de Saúde de Pernambuco, conforme as condições, especificações, quantidades e exigências contidas no Termo de Referência. | F41: 45806 | G41: Autorizada Sucesso | H41: Não Localizado
A42: C.002-ARP.0012.07.2025.GOV.HAM.PE | B42: HOSPITAL REGIONAL DO AGRESTE DR.WALDEMIRO FERREIRA | C42: Consumo | D42: ARP.0012.07.2025.GOV.HAM.PE | E42: Registro de Preços para o fornecimento eventual de material de consumo (aquisição de materiais de almoxarifado) visando atender as necessidades do Hospital Agamenon Magalhães, Hospital Otávio de Freitas, Hospital Regional do Agreste e da Secretaria de Saúde | F42: 45806 | G42: Autorizada Sucesso | H42: Não Localizado
...

Sheet TODOS OS PROCESSOS ATUALIZADOS 
A1: Número da solicitação | B1: Unidade gestora | C1: Tipo da solicitação | D1: Número da ata | E1: Objeto | F1: Data de solicitação | G1: Situação Atual PE INTEGRADO | H1: Situação Monitoramento | I1: Status | J1: Column 20 | K1: Column 21 | L1: Column 22 | M1: Column 23 | N1: Column 24
A2: A.006-ARP.1036.00.2025.GOV.CISAM.PE | B2: HOSPITAL REGIONAL DO AGRESTE DR.WALDEMIRO FERREIRA | C2: Adesão | D2: ARP.1036.00.2025.GOV.CISAM.PE | E2: REGISTRO DE PREÇOS PARA FORNECIMENTO EVENTUAL DE MEDICAMENTOS INJETÁVEIS GRUPO 1 VISANDO ATENDER AS NECESSIDADES DO CISAM/UPE | F2: 45973 | G2: Em configuração | I2: =IF(OR(H2="PROCESSO NÃO ENCONTRADO", G2="PROCESSO NÃO ENCONTRADO"), "PROCESSO NÃO ENCONTRADO", IF(H2=G2,"PROCESSO AINDA NÃO FOI ATUALIZADO","PROCESSO FOI ATUALIZADO")) -> PROCESSO FOI ATUALIZADO
A3: A.002-ARP.0503.00.2025.EXT.HGJMM.RN | B3: HOSPITAL REGIONAL DO AGRESTE DR.WALDEMIRO FERREIRA | C3: Adesão | D3: ARP.0503.00.2025.EXT.HGJMM.RN | E3: Aquisição de Medicamentos - PENICILINAS E CEFALOSPORINAS para atender a demanda desta unidade hospitalar | F3: 45966 | G3: Encaminhada para o orçamento | I3: =IF(OR(H3="PROCESSO NÃO ENCONTRADO", G3="PROCESSO NÃO ENCONTRADO"), "PROCESSO NÃO ENCONTRADO", IF(H3=G3,"PROCESSO AINDA NÃO FOI ATUALIZADO","PROCESSO FOI ATUALIZADO")) -> PROCESSO FOI ATUALIZADO
A4: A.001-ARP.0503.00.2025.EXT.HGJMM.RN | B4: HOSPITAL REGIONAL DO AGRESTE DR.WALDEMIRO FERREIRA | C4: Adesão | D4: ARP.0503.00.2025.EXT.HGJMM.RN | E4: Aquisição de Medicamentos - PENICILINAS E CEFALOSPORINAS para atender a demanda desta unidade hospitalar | F4: 45965 | G4: Cancelada | I4: =IF(OR(H4="PROCESSO NÃO ENCONTRADO", G4="PROCESSO NÃO ENCONTRADO"), "PROCESSO NÃO ENCONTRADO", IF(H4=G4,"PROCESSO AINDA NÃO FOI ATUALIZADO","PROCESSO FOI ATUALIZADO")) -> PROCESSO FOI ATUALIZADO
A5: A.014-ARP.0004.00.2025.GOV.HR.PE | B5: HOSPITAL REGIONAL DO AGRESTE DR.WALDEMIRO FERREIRA | C5: Adesão | D5: ARP.0004.00.2025.GOV.HR.PE | E5: Formação de Ata de Registro de Preços para o fornecimento eventual de produtos médicos (MATERIAL MÉDICO HOSPITALAR), com cessão de equipamentos em regime de comodato, visando atender as necessidades do Hospital da Restauração Gov. Paulo Guerra. | F5: 45961 | G5: Autorizada Sucesso | I5: =IF(OR(H5="PROCESSO NÃO ENCONTRADO", G5="PROCESSO NÃO ENCONTRADO"), "PROCESSO NÃO ENCONTRADO", IF(H5=G5,"PROCESSO AINDA NÃO FOI ATUALIZADO","PROCESSO FOI ATUALIZADO")) -> PROCESSO FOI ATUALIZADO
A6: A.002-ARP.0012.00.2025.EXT.HMAR.PE | B6: HOSPITAL REGIONAL DO AGRESTE DR.WALDEMIRO FERREIRA | C6: Adesão | D6: ARP.0012.00.2025.EXT.HMAR.PE | E6: Aquisição de Materiais e insumos Laboratoriais (LAC I) -RIBBON | F6: 45960 | G6: Em configuração | I6: =IF(OR(H6="PROCESSO NÃO ENCONTRADO", G6="PROCESSO NÃO ENCONTRADO"), "PROCESSO NÃO ENCONTRADO", IF(H6=G6,"PROCESSO AINDA NÃO FOI ATUALIZADO","PROCESSO FOI ATUALIZADO")) -> PROCESSO FOI ATUALIZADO
A7: A.004-ARP.0010.04.2025.GOV.HOF.PE | B7: HOSPITAL REGIONAL DO AGRESTE DR.WALDEMIRO FERREIRA | C7: Adesão | D7: ARP.0010.04.2025.GOV.HOF.PE | E7: Registro de Preços para eventual fornecimento de dispositivos médicos INSUMOS PARA O SERVIÇO DE ENDOSCOPIA. | F7: 45959 | G7: Em configuração | I7: =IF(OR(H7="PROCESSO NÃO ENCONTRADO", G7="PROCESSO NÃO ENCONTRADO"), "PROCESSO NÃO ENCONTRADO", IF(H7=G7,"PROCESSO AINDA NÃO FOI ATUALIZADO","PROCESSO FOI ATUALIZADO")) -> PROCESSO FOI ATUALIZADO
A8: A.026-ARP.0005.12.2025.GOV.HEMOPE.PE | B8: HOSPITAL REGIONAL DO AGRESTE DR.WALDEMIRO FERREIRA | C8: Adesão | D8: ARP.0005.12.2025.GOV.HEMOPE.PE | E8: Formação de Ata de Registro de Preços para o fornecimento eventual de Material Médico Hospitalar - MMH Grupo 3 (eletrodos, equipos para alimentação enteral, parenteral, transfusão de sangue, escovas para limpeza de material, fios, fitas, lâmina de bisturi, fraldas e outros) | F8: 45958 | G8: Em configuração | I8: =IF(OR(H8="PROCESSO NÃO ENCONTRADO", G8="PROCESSO NÃO ENCONTRADO"), "PROCESSO NÃO ENCONTRADO", IF(H8=G8,"PROCESSO AINDA NÃO FOI ATUALIZADO","PROCESSO FOI ATUALIZADO")) -> PROCESSO FOI ATUALIZADO
A9: A.013-ARP.0013.02.2025.GOV.HOF.PE | B9: HOSPITAL REGIONAL DO AGRESTE DR.WALDEMIRO FERREIRA | C9: Adesão | D9: ARP.0013.02.2025.GOV.HOF.PE | E9: REGISTRO DE PREÇOS PARA O FORNECIMENTO DE DISPOSITIVOS MÉDICOS DO TIPO INSUMOS PARA OXIGENOTERAPIA, VISANDO ATENDER AS NECESSIDADES DO HOSPITAL OTÁVIO DE FREITAS. | F9: 45958 | G9: Em configuração | I9: =IF(OR(H9="PROCESSO NÃO ENCONTRADO", G9="PROCESSO NÃO ENCONTRADO"), "PROCESSO NÃO ENCONTRADO", IF(H9=G9,"PROCESSO AINDA NÃO FOI ATUALIZADO","PROCESSO FOI ATUALIZADO")) -> PROCESSO FOI ATUALIZADO
A10: A.002-ARP.0189.00.2025.GOV.HUOC.PE | B10: HOSPITAL REGIONAL DO AGRESTE DR.WALDEMIRO FERREIRA | C10: Adesão | D10: ARP.0189.00.2025.GOV.HUOC.PE | E10: Registro de Preços para o eventual fornecimento de MEDICAMENTOS ANTI-INFLAMATÓRIOS ESTEROIDAIS E NÃO ESTEROIDAIS (SEI nº 0040609437.000105/2025-52) | F10: 45953 | G10: Autorizada Sucesso | I10: =IF(OR(H10="PROCESSO NÃO ENCONTRADO", G10="PROCESSO NÃO ENCONTRADO"), "PROCESSO NÃO ENCONTRADO", IF(H10=G10,"PROCESSO AINDA NÃO FOI ATUALIZADO","PROCESSO FOI ATUALIZADO")) -> PROCESSO FOI ATUALIZADO
A11: A.008-ARP.0008.05.2025.GOV.HGV.PE | B11: HOSPITAL REGIONAL DO AGRESTE DR.WALDEMIRO FERREIRA | C11: Adesão | D11: ARP.0008.05.2025.GOV.HGV.PE | E11: Registro de Preços para o fornecimento eventual de MATERIAIS ESPECIAIS PARA ENDOSCOPIA | F11: 45946 | G11: Cancelada | I11: =IF(OR(H11="PROCESSO NÃO ENCONTRADO", G11="PROCESSO NÃO ENCONTRADO"), "PROCESSO NÃO ENCONTRADO", IF(H11=G11,"PROCESSO AINDA NÃO FOI ATUALIZADO","PROCESSO FOI ATUALIZADO")) -> PROCESSO FOI ATUALIZADO
A12: A.003-ARP.0073.00.2025.GOV.FES-PE.PE | B12: HOSPITAL REGIONAL DO AGRESTE DR.WALDEMIRO FERREIRA | C12: Adesão | D12: ARP.0073.00.2025.GOV.FES-PE.PE | E12: Registro de Preços para o fornecimento eventual de Dispositivos Médicos do tipo Materiais Médicos (Indicadores, cera, e cimento cirúrgico), conforme especificações e quantitativos previstos no Termo de Referência, visando atender as necessidades dos hospitais e estabelecimentos vinculados à Secretaria Estadual de Saúde de Pernambuco | F12: 45946 | G12: Autorizada Sucesso | I12: =IF(OR(H12="PROCESSO NÃO ENCONTRADO", G12="PROCESSO NÃO ENCONTRADO"), "PROCESSO NÃO ENCONTRADO", IF(H12=G12,"PROCESSO AINDA NÃO FOI ATUALIZADO","PROCESSO FOI ATUALIZADO")) -> PROCESSO FOI ATUALIZADO
A13: A.008-ARP.0001.00.2025.GOV.HR.PE | B13: HOSPITAL REGIONAL DO AGRESTE DR.WALDEMIRO FERREIRA | C13: Adesão | D13: ARP.0001.00.2025.GOV.HR.PE | E13: Registro de Preços para o eventual fornecimento de ÓRTESES, PRÓTESES E MATERIAIS ESPECIAIS - OPME’S (TRAUMATO I), visando atender as necessidades do Hospital da Restauração. | F13: 45943 | G13: Autorizada Sucesso | I13: =IF(OR(H13="PROCESSO NÃO ENCONTRADO", G13="PROCESSO NÃO ENCONTRADO"), "PROCESSO NÃO ENCONTRADO", IF(H13=G13,"PROCESSO AINDA NÃO FOI ATUALIZADO","PROCESSO FOI ATUALIZADO")) -> PROCESSO FOI ATUALIZADO
... A713: A.007-ARP.0013.01.2023.GOV.DASIS.PE | B713: HOSPITAL REGIONAL DO AGRESTE DR.WALDEMIRO FERREIRA | C713: Adesão | D713: ARP.0013.01.2023.GOV.DASIS.PE | E713: REGISTRO DE PREÇOS POR UM PERÍODO DE 12 (DOZE) MESES PARA O EVENTUAL FORNECIMENTO DE MEDICAMENTOS INJETÁVEIS BIOLÓGICOS PARA O CENTRO MEDICO HOSPITALAR DA PMPE/CBMPE. | F713: 45156 | G713: Autorizada Integrado | I713: =IF(OR(H713="PROCESSO NÃO ENCONTRADO", G713="PROCESSO NÃO ENCONTRADO"), "PROCESSO NÃO ENCONTRADO", IF(H713=G713,"PROCESSO AINDA NÃO FOI ATUALIZADO","PROCESSO FOI ATUALIZADO")) -> PROCESSO FOI ATUALIZADO
A714: A.002-ARP.0060.01.2023.GOV.HUOC.PE | B714: HOSPITAL REGIONAL DO AGRESTE DR.WALDEMIRO FERREIRA | C714: Adesão | D714: ARP.0060.01.2023.GOV.HUOC.PE | E714: Registro de Preços para eventual fornecimento de MEDICAMENTOS CLÍNICOS GERAIS (SEI nº 0040609437.000428/2022-01) | F714: 45154 | G714: Autorizada Sucesso | I714: =IF(OR(H714="PROCESSO NÃO ENCONTRADO",#REF!= "PROCESSO NÃO ENCONTRADO"), "PROCESSO NÃO ENCONTRADO", IF(H714=#REF!,"PROCESSO AINDA NÃO FOI ATUALIZADO","PROCESSO FOI ATUALIZADO")) -> #REF!
